<?xml version="1.0"?>
<!-- created with Phobos 1.0.1 "Capricious Choutengan" -->
  <robot name="robotaki">

    <link name="new_link">
      <inertial>
        <origin xyz="0 0 -0.06" rpy="0 0 0"/>
        <mass value="2.0"/>
        <inertia ixx="0.04667" ixy="0" ixz="0" iyy="0.04667" iyz="0" izz="0.04"/>
      </inertial>
      <visual name="Cylinder">
        <origin xyz="0 0 -0.06" rpy="-1.5708 0 0"/>
        <geometry>
          <cylinder radius="0.2" length="0.4"/>
        </geometry>
        <material name="Black"/>
      </visual>
      <collision name="Cylinder">
        <origin xyz="0 0 -0.06" rpy="0 0 0"/>
        <geometry>
          <cylinder radius="0.2" length="0.1"/>
        </geometry>
      </collision>
    </link>

    <link name="root">
      <inertial>
        <origin xyz="0 0 -0.15" rpy="0 0 0"/>
        <mass value="2.0"/>
        <inertia ixx="0.05333" ixy="0" ixz="0" iyy="0.05333" iyz="0" izz="0.05333"/>
      </inertial>
      <visual name="minirobot">
        <origin xyz="0 0 -0.15" rpy="0 0 0"/>
        <geometry>
          <box size="0.4 0.4 0.4"/>
        </geometry>
        <material name="Green"/>
      </visual>
      <collision name="minirobot">
        <origin xyz="0 0 -0.15" rpy="0 0 0"/>
        <geometry>
          <box size="0.4 0.4 0.4"/>
        </geometry>
      </collision>
    </link>

    <joint name="new_link.000" type="continuous">
      <origin xyz="0 -0.32 -0.2" rpy="1.5708 0 0"/>
      <parent link="root"/>
      <child link="new_link"/>
      <axis xyz="0 0 1.0"/>
      <limit effort="1.0" velocity="1.0"/>
    </joint>

    <joint name="new_link.000.001" type="continuous">
      <origin xyz="0 -0.32 -0.2" rpy="1.5708 0 0"/>
      <parent link="root"/>
      <child link="new_link"/>
      <axis xyz="0 0 1.0"/>
      <limit effort="1.0" velocity="1.0"/>
    </joint>

    <material name="Black">
      <color rgba="0.00887 0.00887 0.00887 1.0"/>
    </material>

    <material name="Green">
      <color rgba="0.02552 0.35173 0.00685 1.0"/>
    </material>

  </robot>
