<?xml version="1.0" ?>
<!-- =================================================================================== -->
<!-- |    This document was autogenerated by xacro from tutorial.urdf.xacro            | -->
<!-- |    EDITING THIS FILE BY HAND IS NOT RECOMMENDED                                 | -->
<!-- =================================================================================== -->
<robot name="microrobot">
  <material name="white">
    <color rgba="1 1 1 1"/>
  </material>
  <material name="gold">
    <color rgba="1 0.95 0 1"/>
  </material>
  <link name="dummy_link">
    <!-- [ WARN] [1647026126.424341897]: The root link platform_link has an 
        inertia specified in the URDF, but KDL does not support a root link with
        an inertia.  As a workaround, you can add an extra dummy link to your 
        URDF.  -->
  </link>
  <joint name="dl_to_platform" type="fixed">
    <parent link="dummy_link"/>
    <child link="platform_link"/>
  </joint>
  <link name="platform_link">
    <visual>
      <geometry>
        <cylinder length="0.001" radius="0.01825"/>
      </geometry>
      <material name="white"/>
    </visual>
    <collision>
      <geometry>
        <cylinder length="0.001" radius="0.01825"/>
      </geometry>
    </collision>
    <inertial>
      <mass value="0.085"/>
      <inertia ixx="7.084661458333332e-06" ixy="0.0" ixz="0.0" iyy="7.084661458333332e-06" iyz="0.0" izz="2.3591927083333333e-06"/>
    </inertial>
  </link>
  <link name="support_A">
    <visual>
      <geometry>
        <sphere radius="0.002"/>
      </geometry>
      <material name="white"/>
      <origin xyz=" 0.013600000000000001                      -0.008624999999999997                     0"/>
    </visual>
    <collision>
      <geometry>
        <sphere radius="0.002"/>
      </geometry>
    </collision>
    <inertial>
      <mass value="0.05"/>
      <inertia ixx="2.0000000000000004e-08" ixy="0.0" ixz="0.0" iyy="2.0000000000000004e-08" iyz="0.0" izz="2.0000000000000004e-08"/>
    </inertial>
  </link>
  <joint name="platform_to_support_A" type="fixed">
    <parent link="platform_link"/>
    <child link="support_A"/>
  </joint>
  <link name="support_B">
    <visual>
      <geometry>
        <sphere radius="0.002"/>
      </geometry>
      <material name="white"/>
      <origin xyz="0 0.01625 0"/>
    </visual>
    <collision>
      <geometry>
        <sphere radius="0.002"/>
      </geometry>
    </collision>
    <inertial>
      <mass value="0.05"/>
      <inertia ixx="2.0000000000000004e-08" ixy="0.0" ixz="0.0" iyy="2.0000000000000004e-08" iyz="0.0" izz="2.0000000000000004e-08"/>
    </inertial>
  </link>
  <joint name="platform_to_support_B" type="fixed">
    <parent link="platform_link"/>
    <child link="support_B"/>
  </joint>
  <link name="support_C">
    <visual>
      <geometry>
        <sphere radius="0.002"/>
      </geometry>
      <material name="white"/>
      <origin xyz=" -0.013600000000000001                      -0.008624999999999997                     0"/>
    </visual>
    <collision>
      <geometry>
        <sphere radius="0.002"/>
      </geometry>
    </collision>
    <inertial>
      <mass value="0.05"/>
      <inertia ixx="2.0000000000000004e-08" ixy="0.0" ixz="0.0" iyy="2.0000000000000004e-08" iyz="0.0" izz="2.0000000000000004e-08"/>
    </inertial>
  </link>
  <joint name="platform_to_support_C" type="fixed">
    <parent link="platform_link"/>
    <child link="support_C"/>
  </joint>
  <link name="left_motor">
    <visual>
      <geometry>
        <box size="0.008 0.004 0.004"/>
      </geometry>
      <material name="white"/>
      <origin xyz=" -0.014250000000000002                      0                      0.0025"/>
    </visual>
    <collision>
      <geometry>
        <box size="0.008 0.004 0.004"/>
      </geometry>
    </collision>
    <inertial>
      <mass value="0.01"/>
      <inertia ixx="6.666666666666665e-08" ixy="0.0" ixz="0.0" iyy="6.666666666666665e-08" iyz="0.0" izz="6.666666666666665e-08"/>
    </inertial>
  </link>
  <joint name="platform_to_left_motor" type="fixed">
    <parent link="platform_link"/>
    <child link="left_motor"/>
  </joint>
  <link name="left_eccenter">
    <visual>
      <geometry>
        <mesh filename="package://microrobot/meshes/test.stl" scale="0.05 0.05 0.05"/>
      </geometry>
      <material name="gold"/>
      <origin rpy="0 0 0" xyz=" 0                       0                     0"/>
    </visual>
    <collision>
      <geometry>
        <mesh filename="package://microrobot/meshes/test.stl" scale="0.05 0.05 0.05"/>
      </geometry>
    </collision>
    <inertial>
      <mass value="0.00021"/>
      <inertia ixx="0.888081" ixy="0.0" ixz="0.0" iyy="1.305504" iyz="0.0" izz="0.627865"/>
    </inertial>
  </link>
  <joint name="left_motor_to_eccenter" type="continuous">
    <parent link="left_motor"/>
    <child link="left_eccenter"/>
    <axis xyz="1 0 0"/>
    <origin xyz=" -0.00585                     0                   0.0025"/>
  </joint>
  <link name="right_motor">
    <visual>
      <geometry>
        <box size="0.008 0.004 0.004"/>
      </geometry>
      <material name="white"/>
      <origin xyz=" 0.014250000000000002                      0                      0.0025"/>
    </visual>
    <collision>
      <geometry>
        <box size="0.008 0.004 0.004"/>
      </geometry>
    </collision>
    <inertial>
      <mass value="0.01"/>
      <inertia ixx="6.666666666666665e-08" ixy="0.0" ixz="0.0" iyy="6.666666666666665e-08" iyz="0.0" izz="6.666666666666665e-08"/>
    </inertial>
  </link>
  <joint name="platform_to_right_motor" type="fixed">
    <parent link="platform_link"/>
    <child link="right_motor"/>
  </joint>
  <link name="right_eccenter">
    <visual>
      <geometry>
        <mesh filename="package://microrobot/meshes/test.stl" scale="0.05 0.05 0.05"/>
      </geometry>
      <material name="gold"/>
      <origin rpy="0 0 3.141592653589793" xyz=" 0                       0                     0"/>
    </visual>
    <collision>
      <geometry>
        <mesh filename="package://microrobot/meshes/test.stl" scale="0.05 0.05 0.05"/>
      </geometry>
    </collision>
    <inertial>
      <mass value="0.00021"/>
      <inertia ixx="0.888081" ixy="0.0" ixz="0.0" iyy="1.305504" iyz="0.0" izz="0.627865"/>
    </inertial>
  </link>
  <joint name="right_motor_to_eccenter" type="continuous">
    <parent link="right_motor"/>
    <child link="right_eccenter"/>
    <axis xyz="1 0 0"/>
    <origin xyz=" 0.00585                     0                   0.0025"/>
  </joint>
</robot>

