<?xml version="1.0"?>
<robot xmlns:xacro="http://www.ros.org/wiki/xacro" name="microrobot">
    
    <link name="base_link">
    </link>

    <joint name="platform_joint" type="fixed">
        <parent link="base_link"></parent>
        <child link="platform_link"></child>
    </joint>

    <!-- PLATFORM LINK -->

    <link name="platform_link">
        <inertial>
            <mass value="122"/>
            <inertia ixx="0.144"  ixy="0"  ixz="0" iyy="0.083" iyz="0" izz="0.225" />
        </inertial>
        <visual>
            <geometry>
                <mesh filename="package://microrobot/meshes/large_platform_mesh_001.stl"/>
            </geometry>
        </visual>
        <collision>
            <geometry>
                <mesh filename="package://microrobot/meshes/large_platform_mesh_001.stl"/>
            </geometry>
        </collision>
    </link>

    <gazebo reference="platform_link">
        <mu1 value="0.4"/>
        <mu2 value="0.4"/>
    </gazebo>
    
    <!-- LEFT ECCENTER LINK -->

    <joint name="platform_to_left_eccenter_joint" type="continuous">
        <origin xyz="0 0.057 0.008" rpy="0 0 0"/>
        <parent link="platform_link"/>
        <child link="left_eccenter_link"/>
        <axis xyz="0 1 0"/>
    </joint>

    <link name="left_eccenter_link">
        <inertial>
            <origin xyz="0 0 -0.002" rpy="0 0 0"/>
            <mass value="1.825"/>
            <inertia ixx="7.94e-06"  ixy="0"  ixz="0" iyy="1.15e-05" iyz="0" izz="1.431e-05" />
        </inertial>
        <visual>
            <origin xyz="0 0 -0.002" rpy="0 0 0"/>
            <geometry>
                <mesh filename="package://microrobot/meshes/large_eccenter_mesh_001.stl"/>
            </geometry>
        </visual>
        <collision>
            <origin xyz="0 0 -0.002" rpy="0 0 0"/>
            <geometry>
                <mesh filename="package://microrobot/meshes/large_eccenter_mesh_001.stl"/>
            </geometry>
        </collision>
    </link>

    <!-- RIGHT ECCENTER LINK -->

    <joint name="platform_to_right_eccenter_joint" type="continuous">
        <origin xyz="0 -0.057 0.008" rpy="0 0 -3.14"/>
        <parent link="platform_link"/>
        <child link="right_eccenter_link"/>
        <axis xyz="0 1 0"/>
    </joint>

    <link name="right_eccenter_link">
        <inertial>
            <origin xyz="0 0 -0.002" rpy="0 0 0"/> 
            <mass value="1.825"/>
            <inertia ixx="7.94e-06"  ixy="0"  ixz="0" iyy="1.15e-05" iyz="0" izz="1.431e-05" />
        </inertial>
        <visual>
            <origin xyz="0 0 -0.002" rpy="0 0 0"/>         
            <geometry>
                <mesh filename="package://microrobot/meshes/large_eccenter_mesh_001.stl"/>
            </geometry>
        </visual>
        <collision>
            <origin xyz="0 0 -0.002" rpy="0 0 0"/>
            <geometry>
                <mesh filename="package://microrobot/meshes/large_eccenter_mesh_001.stl"/>
            </geometry>
        </collision>
    </link>
</robot>